/*package ExceptionHandling;
class ArithmeTest{
	public static void division(int n1,int n2) {
		int result=0;
		try {
			result=n1/n2;
			
		}catch(ArithmeticException ex){
			System.out.println(ex.getMessage());		
		}catch(ArrayIndexOutOfBoundsException ex) {
			System.out.println(ex.getMessage());
		}catch(Exception ex){
			System.out.println(ex.getMessage());
			
		}
		finally {
			System.out.println("Division:"+result);
		}
		System.out.println("remaining code....");
	}
}

public class ExceptionExamp2 {
	public static void main(String[] args) {
		ArithmeticTest.divison(24, 6);
	}

}*/
